Workbook

Sheet Касса
B2: понедельник | E2: Утверждаю
B3: 1 сентября | E3: Директор ООО «Патриот-Москва»
B4: МЕНЮ СТОЛОВОЙ "ПАТРИОТ" | G4: _____________ Попова О.И.
A5: г. Москва,ул. Овчинниковская наб.,д.18/1 стр.2
A6: ЗАВТРАКИ | B6: Вес/ед.изм. | C6: Цена, руб. | E6: ПЕРВЫЕ БЛЮДА | F6: Вес/ед.изм. | G6: Цена, руб.
A7: Блин с курицей и грибами | B7: 1шт | C7: 105 | E7: Бульон куриный с яйцом | F7: 250/20г | G7: 110
A8: Блин с творогом и изюмом | B8: 1шт | C8: 95 | E8: Рыбный суп с картофелем | F8: 250 | G8: 165
A9: Блинчик без начинки | B9: 1шт | C9: 40 | E9: Солянка домашняя со сметаной | F9: 250/15г | G9: 150
A10: Горячий бутерброд с ветчиной | B10: 100г | C10: 120 | E10: Суп-пюре овощной с гренками | F10: 250/10г | G10: 150
A11: Горячий бутерброд с томатами | B11: 100г | C11: 105 | E11: БЛЮДА ИЗ МЯСА
A12: Дополнительно: ветчина,помидоры,сыр | B12: 20г | C12: 50 | E12: Азу из говядины | F12: 75/75г | G12: 325
A13: Драники картофельные | B13: 50г | C13: 70 | E13: Бифштекс рубленый с маринованныи луком | F13: 100/20г | G13: 290
A14: Каша геркулесовая на кокосовом молоке | B14: 200г | C14: 110 | E14: Буженина | F14: 100г | G14: 275
A15: Каша Дружба (рис, пшено) молочная | B15: 200г | C15: 100 | E15: Говядина томленая в вишневом соусе | F15: 100/50г | G15: 395
A16: Каша манная молочная | B16: 200г | C16: 100 | E16: Ежики Домашние в красном соусе | F16: 100/50г | G16: 200
A17: Кесадилья с курицей и грибами | B17: 100г | C17: 160 | E17: Котлета жареная курица/свинина | F17: 100г | G17: 195
A18: Колбаса жареная | B18: 50г | C18: 95 | E18: БЛЮДА ИЗ ПТИЦЫ
A19: Крок-мадам | B19: 160г | C19: 190 | E19: Грудка куриная отварная | F19: 100г | G19: 215
A20: Оладьи из кабачков | B20: 50г | C20: 70 | E20: Грудка куриная гриль | F20: 100г | G20: 215
A21: Омлет на заказ | B21: 120г | C21: 125 | E21: Грудка запеченая со шпинатом | F21: 100г | G21: 215
A22: Омлет/Омлет с болгарским перцем | B22: 170/200 | C22: 140/150 | E22: Котлета куриная паровая | F22: 100г | G22: 195
A23: Пудинг творожный с курагой | B23: 125г | C23: 190 | E23: Котлета Пожарская в сухарях | F23: 110г | G23: 205
A24: Сосиска отварная /жареная | B24: 1шт | C24: 100 | E24: Плов с курицей | F24: 250г | G24: 240
A25: Сосиска с беконом | B25: 1шт | C25: 155 | E25: БЛЮДА ИЗ РЫБЫ
A26: Сосиска с сыром | B26: 1шт | C26: 125 | E26: Котлета по-приморски | F26: 100г | G26: 225
A27: Сырники | B27: 1шт | C27: 90 | E27: Пангасиус под маринадом | F27: 100г | G27: 220
A28: Хашбраун с яйцом и беконом | B28: 120г | C28: 170 | E28: Филе форели гриль | F28: 100г | G28: 500
A29: Яйцо жареное/отварное | B29: 1шт | C29: 55/50 | E29: Хек жареный по-домашнему | F29: вес/100г | G29: 230
A30: САЛАТЫ и ХОЛОДНЫЕ ЗАКУСКИ | E30: ГАРНИРЫ
A31: Греческий салат | B31: 175г | C31: 250 | E31: Баклажаны с томатами гриль и песто | F31: 150г | G31: 140
A32: Жозефина | B32: 100г | C32: 110 | E32: Гречка отварная | F32: 150г | G32: 65
A33: Капуста с перцем | B33: 100г | C33: 70 | E33: Картофель отварной с зеленью | F33: 200г | G33: 120
A34: Коулслоу | B34: 100г | C34: 75 | E34: Картофель по-деревенски | F34: 150г | G34: 120
A35: Куропатка салат | B35: 100г | C35: 115 | E35: Кукуруза с фасолью и болгарским перцем | F35: 150г | G35: 150
A36: Мясной салат | B36: 100г | C36: 130 | E36: Кускус с грибами,луком и морковью | F36: 150г | G36: 110
A37: Помидоры с базиликовой заправкой | B37: 100г | C37: 90 | E37: Макароны отварные | F37: 150г | G37: 70
A38: Редис с огурцом и растительным маслом | B38: 100г | C38: 90 | E38: Рис отварной | F38: 150г | G38: 70
A39: Салат Баклажаны и сыр фета | B39: 100г | C39: 125 | E39: НАПИТКИ
A40: Салат с сайрой | B40: 100г | C40: 110 | E40: Напиток охл.в стакане/в бутылке | F40: 200/300мл | G40: 60/80
A41: Свекла с яблоком и арахисом | B41: 100г | C41: 80 | E41: Смузи клубника/шпинат | F41: 300мл | G41: 240/240
...

Sheet Завтрак
B1: =Касса!B2
B2: =Касса!B3 | C2: Утверждаю
B3: Директор ООО "Патриот-Москва"
A4: МЕНЮ СТОЛОВОЙ "ПАТРИОТ" | C4: _________________Попова О.И.
A5: г.Москва,Овчинниковская наб.,д.18/1,стр.2
A6: =Касса!B6 | B6: ЗАВТРАК | C6: =Касса!C6
A7: =Касса!B7 | B7: =Касса!A7 | C7: =Касса!C7
A8: =Касса!B8 | B8: =Касса!A8 | C8: =Касса!C8
A9: =Касса!B9 | B9: =Касса!A9 | C9: =Касса!C9
A10: =Касса!B10 | B10: =Касса!A10 | C10: =Касса!C10
A11: =Касса!B11 | B11: =Касса!A11 | C11: =Касса!C11
A12: =Касса!B12 | B12: =Касса!A12 | C12: =Касса!C12
A13: =Касса!B13 | B13: =Касса!A13 | C13: =Касса!C13
A14: =Касса!B14 | B14: =Касса!A14 | C14: =Касса!C14
A15: =Касса!B15 | B15: =Касса!A15 | C15: =Касса!C15
A16: =Касса!B16 | B16: =Касса!A16 | C16: =Касса!C16
A17: =Касса!B17 | B17: =Касса!A17 | C17: =Касса!C17
A18: =Касса!B18 | B18: =Касса!A18 | C18: =Касса!C18
... A29: =Касса!B29 | B29: =Касса!A29 | C29: =Касса!C29
A32: =Касса!A60
A33: =Касса!A61

Sheet Обед
B1: =Касса!B2
B2: =Касса!B3 | C2: Утверждаю
C3: Директор ООО "Патриот-Москва"
A4: МЕНЮ СТОЛОВОЙ "ПАТРИОТ" | C4: _________________Попова О.И.
A5: г.Москва,Овчинниковская наб.,д.18/1,стр.2
A6: Вес/ед.изм. | B6: САЛАТЫ и ХОЛОДНЫЕ ЗАКУСКИ | C6: Цена, руб.
A7: =Касса!B31 | B7: =Касса!A31 | C7: =Касса!C31
A8: =Касса!B32 | B8: =Касса!A32 | C8: =Касса!C32
A9: =Касса!B33 | B9: =Касса!A33 | C9: =Касса!C33
A10: =Касса!B34 | B10: =Касса!A34 | C10: =Касса!C34
A11: =Касса!B35 | B11: =Касса!A35 | C11: =Касса!C35
A12: =Касса!B36 | B12: =Касса!A36 | C12: =Касса!C36
A13: =Касса!B37 | B13: =Касса!A37 | C13: =Касса!C37
A14: =Касса!B38 | B14: =Касса!A38 | C14: =Касса!C38
A15: =Касса!B39 | B15: =Касса!A39 | C15: =Касса!C39
A16: =Касса!B40 | B16: =Касса!A40 | C16: =Касса!C40
A17: =Касса!B41 | B17: =Касса!A41 | C17: =Касса!C41
A18: =Касса!B42 | B18: =Касса!A42 | C18: =Касса!C42
B19: ПЕРВЫЕ БЛЮДА
A20: =Касса!F7 | B20: =Касса!E7 | C20: =Касса!G7
A21: =Касса!F8 | B21: =Касса!E8 | C21: =Касса!G8
A22: =Касса!F9 | B22: =Касса!E9 | C22: =Касса!G9
A23: =Касса!F10 | B23: =Касса!E10 | C23: =Касса!G10
B24: БЛЮДА ИЗ МЯСА
A25: =Касса!F12 | B25: =Касса!E12 | C25: =Касса!G12
A26: =Касса!F13 | B26: =Касса!E13 | C26: =Касса!G13
A27: =Касса!F14 | B27: =Касса!E14 | C27: =Касса!G14
A28: =Касса!F15 | B28: =Касса!E15 | C28: =Касса!G15
A29: =Касса!F16 | B29: =Касса!E16 | C29: =Касса!G16
A30: =Касса!F17 | B30: =Касса!E17 | C30: =Касса!G17
B31: БЛЮДА ИЗ ПТИЦЫ
A32: =Касса!F19 | B32: =Касса!E19 | C32: =Касса!G19
A33: =Касса!F20 | B33: =Касса!E20 | C33: =Касса!G20
A34: =Касса!F21 | B34: =Касса!E21 | C34: =Касса!G21
A35: =Касса!F22 | B35: =Касса!E22 | C35: =Касса!G22
A36: =Касса!F23 | B36: =Касса!E23 | C36: =Касса!G23
A37: =Касса!F24 | B37: =Касса!E24 | C37: =Касса!G24
B38: БЛЮДА ИЗ РЫБЫ
A39: =Касса!F26 | B39: =Касса!E26 | C39: =Касса!G26
A40: =Касса!F27 | B40: =Касса!E27 | C40: =Касса!G27
...

Sheet Гц
B2: =Касса!B2 | E2: Утверждаю
B3: =Касса!B3 | E3: Директор ООО «Патриот-Москва»
B4: МЕНЮ СТОЛОВОЙ "ПАТРИОТ" | G4: _____________ Попова О.И.
A5: г. Москва,ул. Овчинниковская наб.,д.18/1 стр.2
A6: ЗАВТРАКИ | E6: ПЕРВЫЕ БЛЮДА
A7: =Касса!A7 | E7: =Касса!E7
A8: =Касса!A8 | E8: =Касса!E8
A9: =Касса!A9 | E9: =Касса!E9
A10: =Касса!A10 | E10: =Касса!E10
A11: =Касса!A11 | E11: БЛЮДА ИЗ МЯСА
A12: =Касса!A12 | E12: =Касса!E12
A13: =Касса!A13 | E13: =Касса!E13
A14: =Касса!A14 | E14: =Касса!E14
A15: =Касса!A15 | E15: =Касса!E15
A16: =Касса!A16 | E16: =Касса!E16
A17: =Касса!A17 | E17: =Касса!E17
A18: =Касса!A18 | E18: БЛЮДА ИЗ ПТИЦЫ
A19: =Касса!A19 | E19: =Касса!E19
A20: =Касса!A20 | E20: =Касса!E20
A21: =Касса!A21 | E21: =Касса!E21
A22: =Касса!A22 | E22: =Касса!E22
A23: =Касса!A23 | E23: =Касса!E23
A24: =Касса!A24 | E24: =Касса!E24
A25: =Касса!A25 | E25: БЛЮДА ИЗ РЫБЫ
A26: =Касса!A26 | E26: =Касса!E26
A27: =Касса!A27 | E27: =Касса!E27
A28: =Касса!A28 | E28: =Касса!E28
A29: =Касса!A29 | E29: =Касса!E29
E30: ГАРНИРЫ
E31: =Касса!E31
E32: =Касса!E32
E33: =Касса!E33
E34: =Касса!E34
E35: =Касса!E35
E36: =Касса!E36
E37: =Касса!E37
E38: =Касса!E38

Sheet Хц
B2: =Касса!B2 | E2: Утверждаю
B3: =Касса!B3 | E3: Директор ООО «Патриот-Москва»
B4: МЕНЮ СТОЛОВОЙ "ПАТРИОТ" | G4: _____________ Попова О.И.
A5: г. Москва,ул. Овчинниковская наб.,д.18/1 стр.2
A6: САЛАТЫ и ХОЛОДНЫЕ ЗАКУСКИ | B6: Выходы | C6: План
A7: =Касса!A31 | B7: =Касса!B31
A8: =Касса!A32 | B8: =Касса!B32
A9: =Касса!A33 | B9: =Касса!B33
A10: =Касса!A34 | B10: =Касса!B34
A11: =Касса!A35 | B11: =Касса!B35
A12: =Касса!A36 | B12: =Касса!B36
A13: =Касса!A37 | B13: =Касса!B37
A14: =Касса!A38 | B14: =Касса!B38
A15: =Касса!A39 | B15: =Касса!B39
A16: =Касса!A40 | B16: =Касса!B40
A17: =Касса!A41 | B17: =Касса!B41
A18: =LEFT(Касса!A42,FIND("/",Касса!A42)-1) | B18: =LEFT(Касса!B42,FIND("/",Касса!B42)-1) & "г"
A19: ="Цезарь "&MID(Касса!A42,FIND("/",Касса!A42)+1,999) | B19: =MID(Касса!B42,FIND("/",Касса!B42)+1,999)
A20: Всего: | C20: =SUM(C7:C19)
A22: СЭНДВИЧИ
A23: =Касса!A44 | B23: =Касса!B44
A24: =Касса!A45 | B24: =Касса!B45
A25: =Касса!A46 | B25: =Касса!B46
A26: =Касса!A47 | B26: =Касса!B47

Sheet Раздача
B2: =Касса!B2 | E2: Утверждаю
B3: =Касса!B3 | E3: Директор ООО «Патриот-Москва»
B4: МЕНЮ СТОЛОВОЙ "ПАТРИОТ" | G4: _____________ Попова О.И.
A5: г. Москва,ул. Овчинниковская наб.,д.18/1 стр.2
A6: ЗАВТРАКИ | B6: Питание | C6: Остатки | E6: ПЕРВЫЕ БЛЮДА | F6: Питание | G6: Остатки
A7: =Касса!A7 | E7: =Касса!E7
A8: =Касса!A8 | E8: =Касса!E8
A9: =Касса!A9 | E9: =Касса!E9
A10: =Касса!A10 | E10: =Касса!E10
A11: =Касса!A11 | E11: БЛЮДА ИЗ МЯСА
A12: =Касса!A12 | E12: =Касса!E12
A13: =Касса!A13 | E13: =Касса!E13
A14: =Касса!A14 | E14: =Касса!E14
A15: =Касса!A15 | E15: =Касса!E15
A16: =Касса!A16 | E16: =Касса!E16
A17: =Касса!A17 | E17: =Касса!E17
A18: =Касса!A18 | E18: БЛЮДА ИЗ ПТИЦЫ
A19: =Касса!A19 | E19: =Касса!E19
A20: =Касса!A20 | E20: =Касса!E20
A21: =Касса!A21 | E21: =Касса!E21
A22: =Касса!A22 | E22: =Касса!E22
A23: =Касса!A23 | E23: =Касса!E23
A24: =Касса!A24 | E24: =Касса!E24
A25: =Касса!A25 | E25: БЛЮДА ИЗ РЫБЫ
A26: =Касса!A26 | E26: =Касса!E26
A27: =Касса!A27 | E27: =Касса!E27
A28: =Касса!A28 | E28: =Касса!E28
A29: =Касса!A29 | E29: =Касса!E29
A30: САЛАТЫ и ХОЛОДНЫЕ ЗАКУСКИ | E30: ГАРНИРЫ
A31: =Касса!A31 | E31: =Касса!E31
A32: =Касса!A32 | E32: =Касса!E32
A33: =Касса!A33 | E33: =Касса!E33
A34: =Касса!A34 | E34: =Касса!E34
A35: =Касса!A35 | E35: =Касса!E35
A36: =Касса!A36 | E36: =Касса!E36
A37: =Касса!A37 | E37: =Касса!E37
A38: =Касса!A38 | E38: =Касса!E38
A39: =Касса!A39
A40: =Касса!A40
A41: =Касса!A41
...
