Workbook

Sheet Касса
B2: понедельник | D2: Утверждаю
B3: 1 сентября | D3: Директор ООО «Патриот-Москва»
B4: МЕНЮ СТОЛОВОЙ "ПАТРИОТ" | F4: _____________ Попова О.И.
A5: г. Москва,ул. Овчинниковская наб.,д.18/1 стр.2
A6: ЗАВТРАКИ | B6: Вес/ед.изм. | C6: Цена, руб. | D6: ПЕРВЫЕ БЛЮДА | E6: Вес/ед.изм. | F6: Цена, руб.
D11: БЛЮДА ИЗ МЯСА
D18: БЛЮДА ИЗ ПТИЦЫ
D25: БЛЮДА ИЗ РЫБЫ
A28: САЛАТЫ и ХОЛОДНЫЕ ЗАКУСКИ
D30: ГАРНИРЫ
D39: НАПИТКИ
D40: Напиток охл.в стакане/в бутылке | E40: 200/300мл | F40: 65/85
D41: Смузи смородина/малина/клубника/шпинат | E41: 300мл | F41: 250
A42: СЭНДВИЧИ | D42: Фреш апельсиновый/морковный | E42: 300мл | F42: 350/225
A43: Сэндвич с бужениной | B43: 180г | C43: 210 | D43: Чай фруктовый в ассортименте | E43: 225мл | F43: 95
A44: Сэндвич с ветчиной и сыром | B44: 180г | C44: 210 | D44: ХЛЕБ
A45: Сэндвич с куриной грудкой | B45: 180г | C45: 210 | D45: Мини-багет | E45: шт/45г | F45: 20
A46: Сэндвич с форелью | B46: 180г | C46: 325 | D46: Хлеб Пшеничный/Ржаной | E46: кусок/25г | F46: 10
A47: ПЕЛЬМЕНИ | D47: СОУСЫ
A48: Манты по-домашнему | B48: 250г | C48: 240 | D48: Варенье клубничное | E48: 50г | F48: 50
A49: Пельмени Домашние | B49: 240г | C49: 255 | D49: Горчица | E49: 10г | F49: 20
A50: Пельмени Патриот | B50: 240г | C50: 260 | D50: Кетчуп | E50: 30г | F50: 50
A51: Пельмени с говядиной | B51: 240г | C51: 310 | D51: Майонез | E51: 30г | F51: 50
A52: Пельмени с индейкой | B52: 240г | C52: 290 | D52: Подливка к горячему и гарнирам | E52: 30г | F52: 20
A53: Пельмени с курицей | B53: 240г | C53: 255 | D53: Сгущеное молоко | E53: 50г | F53: 70
A54: Пельмени с рыбой | B54: 240г | C54: 295 | D54: Сметана | E54: 50г | F54: 55
A55: ВАРЕНИКИ | D55: Соус от Николаевича | E55: 50г | F55: 55
A56: Вареники с вишней | B56: 250г | C56: 275 | D56: Хрен | E56: 10г | F56: 20
A57: Вареники с картофелем | B57: 250г | C57: 180
A58: Вареники с картофелем и гриб. | B58: 250г | C58: 195
A59: Вареники с квашеной капустой | B59: 250г | C59: 180
A60: Вареники с сулугуни и адыгейс. | B60: 250г | C60: 285
A61: Вареники с творогом | B61: 250г | C61: 240
A62: *ПРИ НАЛИЧИИ У ВАС АЛЛЕРГИИ, УТОЧНЯЙТЕ ИНФОРМАЦИЮ О ПОДРОБНОМ СОСТАВЕ БЛЮД В МЕНЮ С ВЫХОДОМ НА ДОСКЕ ПОТРЕБИТЕЛЯ.
A63: Блюда могут содержать следы молочных продуктов, яичных продуктов, рыбы, моллюсков, кунжута, горчицы, сои, злаков, содержащих глютен, арахиса, аспартама, диоксида серы и сульфатов, люпина, орехов, ракообразных, сельдерея. Допускается использовать аналогичные указанным компоненты, отечественного или импортного производства, соответствующие нормативным и правовым документам Российской Федерации и Таможенного союза.

Sheet Завтрак
B1: =Касса!B2 -> понедельник
B2: =Касса!B3 -> 1 сентября | C2: Утверждаю
B3: Директор ООО "Патриот-Москва"
A4: МЕНЮ СТОЛОВОЙ "ПАТРИОТ" | C4: _________________Попова О.И.
A5: г.Москва,Овчинниковская наб.,д.18/1,стр.2
A6: =Касса!B6 -> Вес/ед.изм. | B6: ЗАВТРАК | C6: =Касса!C6 -> Цена, руб.
A7: =Касса!B7 -> 0 | B7: =Касса!A7 -> 0 | C7: =Касса!C7 -> 0
A8: =Касса!B8 -> 0 | B8: =Касса!A8 -> 0 | C8: =Касса!C8 -> 0
A9: =Касса!B9 -> 0 | B9: =Касса!A9 -> 0 | C9: =Касса!C9 -> 0
A10: =Касса!B10 -> 0 | B10: =Касса!A10 -> 0 | C10: =Касса!C10 -> 0
A11: =Касса!B11 -> 0 | B11: =Касса!A11 -> 0 | C11: =Касса!C11 -> 0
A12: =Касса!B12 -> 0 | B12: =Касса!A12 -> 0 | C12: =Касса!C12 -> 0
A13: =Касса!B13 -> 0 | B13: =Касса!A13 -> 0 | C13: =Касса!C13 -> 0
A14: =Касса!B14 -> 0 | B14: =Касса!A14 -> 0 | C14: =Касса!C14 -> 0
A15: =Касса!B15 -> 0 | B15: =Касса!A15 -> 0 | C15: =Касса!C15 -> 0
A16: =Касса!B16 -> 0 | B16: =Касса!A16 -> 0 | C16: =Касса!C16 -> 0
A17: =Касса!B17 -> 0 | B17: =Касса!A17 -> 0 | C17: =Касса!C17 -> 0
A18: =Касса!B18 -> 0 | B18: =Касса!A18 -> 0 | C18: =Касса!C18 -> 0
... A27: =Касса!B27 -> 0 | B27: =Касса!A27 -> 0 | C27: =Касса!C27 -> 0
A30: =Касса!A62 -> *ПРИ НАЛИЧИИ У ВАС АЛЛЕРГИИ, УТОЧНЯЙТЕ ИНФОРМАЦИЮ О ПОДРОБНОМ СОСТАВЕ БЛЮД В МЕНЮ С ВЫХОДОМ НА ДОСКЕ ПОТРЕБИТЕЛЯ.
A31: =Касса!A63 -> Блюда могут содержать следы молочных продуктов, яичных продуктов, рыбы, моллюсков, кунжута, горчицы, сои, злаков, содержащих глютен, арахиса, аспартама, диоксида серы и сульфатов, люпина, орехов, ракообразных, сельдерея. Допускается использовать аналогичные указанным компоненты, отечественного или импортного производства, соответствующие нормативным и правовым документам Российской Федерации и Таможенного союза.

Sheet Обед
B1: =Касса!B2 -> понедельник
B2: =Касса!B3 -> 1 сентября | C2: Утверждаю
C3: Директор ООО "Патриот-Москва"
A4: МЕНЮ СТОЛОВОЙ "ПАТРИОТ" | C4: _________________Попова О.И.
A5: г.Москва,Овчинниковская наб.,д.18/1,стр.2
A6: Вес/ед.изм. | B6: САЛАТЫ и ХОЛОДНЫЕ ЗАКУСКИ | C6: Цена, руб.
A7: =Касса!B29 -> 0 | B7: =Касса!A29 -> 0 | C7: =Касса!C29 -> 0
A8: =Касса!B30 -> 0 | B8: =Касса!A30 -> 0 | C8: =Касса!C30 -> 0
A9: =Касса!B31 -> 0 | B9: =Касса!A31 -> 0 | C9: =Касса!C31 -> 0
A10: =Касса!B32 -> 0 | B10: =Касса!A32 -> 0 | C10: =Касса!C32 -> 0
A11: =Касса!B33 -> 0 | B11: =Касса!A33 -> 0 | C11: =Касса!C33 -> 0
A12: =Касса!B34 -> 0 | B12: =Касса!A34 -> 0 | C12: =Касса!C34 -> 0
A13: =Касса!B35 -> 0 | B13: =Касса!A35 -> 0 | C13: =Касса!C35 -> 0
A14: =Касса!B36 -> 0 | B14: =Касса!A36 -> 0 | C14: =Касса!C36 -> 0
A15: =Касса!B37 -> 0 | B15: =Касса!A37 -> 0 | C15: =Касса!C37 -> 0
A16: =Касса!B38 -> 0 | B16: =Касса!A38 -> 0 | C16: =Касса!C38 -> 0
A17: =Касса!B39 -> 0 | B17: =Касса!A39 -> 0 | C17: =Касса!C39 -> 0
A18: =Касса!B40 -> 0 | B18: =Касса!A40 -> 0 | C18: =Касса!C40 -> 0
A19: =Касса!B41 -> 0 | B19: =Касса!A41 -> 0 | C19: =Касса!C41 -> 0
B20: ПЕРВЫЕ БЛЮДА
A21: =Касса!E7 -> 0 | B21: =Касса!D7 -> 0 | C21: =Касса!F7 -> 0
A22: =Касса!E8 -> 0 | B22: =Касса!D8 -> 0 | C22: =Касса!F8 -> 0
A23: =Касса!E9 -> 0 | B23: =Касса!D9 -> 0 | C23: =Касса!F9 -> 0
A24: =Касса!E10 -> 0 | B24: =Касса!D10 -> 0 | C24: =Касса!F10 -> 0
B25: БЛЮДА ИЗ МЯСА
A26: =Касса!E12 -> 0 | B26: =Касса!D12 -> 0 | C26: =Касса!F12 -> 0
A27: =Касса!E13 -> 0 | B27: =Касса!D13 -> 0 | C27: =Касса!F13 -> 0
A28: =Касса!E14 -> 0 | B28: =Касса!D14 -> 0 | C28: =Касса!F14 -> 0
A29: =Касса!E15 -> 0 | B29: =Касса!D15 -> 0 | C29: =Касса!F15 -> 0
A30: =Касса!E16 -> 0 | B30: =Касса!D16 -> 0 | C30: =Касса!F16 -> 0
A31: =Касса!E17 -> 0 | B31: =Касса!D17 -> 0 | C31: =Касса!F17 -> 0
B32: БЛЮДА ИЗ ПТИЦЫ
A33: =Касса!E19 -> 0 | B33: =Касса!D19 -> 0 | C33: =Касса!F19 -> 0
A34: =Касса!E20 -> 0 | B34: =Касса!D20 -> 0 | C34: =Касса!F20 -> 0
A35: =Касса!E21 -> 0 | B35: =Касса!D21 -> 0 | C35: =Касса!F21 -> 0
A36: =Касса!E22 -> 0 | B36: =Касса!D22 -> 0 | C36: =Касса!F22 -> 0
A37: =Касса!E23 -> 0 | B37: =Касса!D23 -> 0 | C37: =Касса!F23 -> 0
A38: =Касса!E24 -> 0 | B38: =Касса!D24 -> 0 | C38: =Касса!F24 -> 0
B39: БЛЮДА ИЗ РЫБЫ
A40: =Касса!E26 -> 0 | B40: =Касса!D26 -> 0 | C40: =Касса!F26 -> 0
...

Sheet Гц
B2: =Касса!B2 -> понедельник | E2: Утверждаю
B3: =Касса!B3 -> 1 сентября | E3: Директор ООО «Патриот-Москва»
B4: МЕНЮ СТОЛОВОЙ "ПАТРИОТ" | G4: _____________ Попова О.И.
A5: г. Москва,ул. Овчинниковская наб.,д.18/1 стр.2
A6: ЗАВТРАКИ | E6: ПЕРВЫЕ БЛЮДА
A7: =Касса!A7 -> 0 | E7: =Касса!D7 -> 0
A8: =Касса!A8 -> 0 | E8: =Касса!D8 -> 0
A9: =Касса!A9 -> 0 | E9: =Касса!D9 -> 0
A10: =Касса!A10 -> 0 | E10: =Касса!D10 -> 0
A11: =Касса!A11 -> 0 | E11: БЛЮДА ИЗ МЯСА
A12: =Касса!A12 -> 0 | E12: =Касса!D12 -> 0
A13: =Касса!A13 -> 0 | E13: =Касса!D13 -> 0
A14: =Касса!A14 -> 0 | E14: =Касса!D14 -> 0
A15: =Касса!A15 -> 0 | E15: =Касса!D15 -> 0
A16: =Касса!A16 -> 0 | E16: =Касса!D16 -> 0
A17: =Касса!A17 -> 0 | E17: =Касса!D17 -> 0
A18: =Касса!A18 -> 0 | E18: БЛЮДА ИЗ ПТИЦЫ
A19: =Касса!A19 -> 0 | E19: =Касса!D19 -> 0
A20: =Касса!A20 -> 0 | E20: =Касса!D20 -> 0
A21: =Касса!A21 -> 0 | E21: =Касса!D21 -> 0
A22: =Касса!A22 -> 0 | E22: =Касса!D22 -> 0
A23: =Касса!A23 -> 0 | E23: =Касса!D23 -> 0
A24: =Касса!A24 -> 0 | E24: =Касса!D24 -> 0
A25: =Касса!A25 -> 0 | E25: БЛЮДА ИЗ РЫБЫ
A26: =Касса!A26 -> 0 | E26: =Касса!D26 -> 0
A27: =Касса!A27 -> 0 | E27: =Касса!D27 -> 0
E28: =Касса!D28 -> 0
E29: =Касса!D29 -> 0
E30: ГАРНИРЫ
E31: =Касса!D31 -> 0
E32: =Касса!D32 -> 0
E33: =Касса!D33 -> 0
E34: =Касса!D34 -> 0
E35: =Касса!D35 -> 0
E36: =Касса!D36 -> 0
E37: =Касса!D37 -> 0
E38: =Касса!D38 -> 0

Sheet Хц
B2: =Касса!B2 -> понедельник | E2: Утверждаю
B3: =Касса!B3 -> 1 сентября | E3: Директор ООО «Патриот-Москва»
B4: МЕНЮ СТОЛОВОЙ "ПАТРИОТ" | G4: _____________ Попова О.И.
A5: г. Москва,ул. Овчинниковская наб.,д.18/1 стр.2
A6: САЛАТЫ и ХОЛОДНЫЕ ЗАКУСКИ | B6: Выходы | C6: План
A7: =Касса!A29 -> 0 | B7: =Касса!B29 -> 0
A8: =Касса!A30 -> 0 | B8: =Касса!B30 -> 0
A9: =Касса!A31 -> 0 | B9: =Касса!B31 -> 0
A10: =Касса!A32 -> 0 | B10: =Касса!B32 -> 0
A11: =Касса!A33 -> 0 | B11: =Касса!B33 -> 0
A12: =Касса!A34 -> 0 | B12: =Касса!B34 -> 0
A13: =Касса!A35 -> 0 | B13: =Касса!B35 -> 0
A14: =Касса!A36 -> 0 | B14: =Касса!B36 -> 0
A15: =Касса!A37 -> 0 | B15: =Касса!B37 -> 0
A16: =Касса!A38 -> 0 | B16: =Касса!B38 -> 0
A17: =Касса!A39 -> 0 | B17: =Касса!B39 -> 0
A18: =Касса!A40 -> 0 | B18: =Касса!B40 -> 0
A19: =Касса!A41 -> 0 | B19: =Касса!B41 -> 0 | C19: 4 и 4
A21: Всего: | C21: =SUM(C7:D19)+4+4 -> 8 | D21: =SUM(D7:E21)+4+4 -> 0
A22: СЭНДВИЧИ
A23: =Касса!A43 -> Сэндвич с бужениной | B23: =Касса!B43 -> 180г | C23: 2
A24: =Касса!A44 -> Сэндвич с ветчиной и сыром | B24: =Касса!B44 -> 180г | C24: 5
A25: =Касса!A45 -> Сэндвич с куриной грудкой | B25: =Касса!B45 -> 180г | C25: 5
A26: =Касса!A46 -> Сэндвич с форелью | B26: =Касса!B46 -> 180г | C26: 2

Sheet Раздача
B2: =Касса!B2 -> понедельник | E2: Утверждаю
B3: =Касса!B3 -> 1 сентября | E3: Директор ООО «Патриот-Москва»
B4: МЕНЮ СТОЛОВОЙ "ПАТРИОТ" | G4: _____________ Попова О.И.
A5: г. Москва,ул. Овчинниковская наб.,д.18/1 стр.2
A6: ЗАВТРАКИ | B6: Питание | C6: Остатки | E6: ПЕРВЫЕ БЛЮДА | F6: Питание | G6: Остатки
A7: =Касса!A7 -> 0 | E7: =Касса!D7 -> 0
A8: =Касса!A8 -> 0 | E8: =Касса!D8 -> 0
A9: =Касса!A9 -> 0 | E9: =Касса!D9 -> 0
A10: =Касса!A10 -> 0 | E10: =Касса!D10 -> 0
A11: =Касса!A11 -> 0 | E11: БЛЮДА ИЗ МЯСА
A12: =Касса!A12 -> 0 | E12: =Касса!D12 -> 0
A13: =Касса!A13 -> 0 | E13: =Касса!D13 -> 0
A14: =Касса!A14 -> 0 | E14: =Касса!D14 -> 0
A15: =Касса!A15 -> 0 | E15: =Касса!D15 -> 0
A16: =Касса!A16 -> 0 | E16: =Касса!D16 -> 0
A17: =Касса!A17 -> 0 | E17: =Касса!D17 -> 0
A18: =Касса!A18 -> 0 | E18: БЛЮДА ИЗ ПТИЦЫ
A19: =Касса!A19 -> 0 | E19: =Касса!D19 -> 0
A20: =Касса!A20 -> 0 | E20: =Касса!D20 -> 0
A21: =Касса!A21 -> 0 | E21: =Касса!D21 -> 0
A22: =Касса!A22 -> 0 | E22: =Касса!D22 -> 0
A23: =Касса!A23 -> 0 | E23: =Касса!D23 -> 0
A24: =Касса!A24 -> 0 | E24: =Касса!D24 -> 0
A25: =Касса!A25 -> 0 | E25: БЛЮДА ИЗ РЫБЫ
A26: =Касса!A26 -> 0 | E26: =Касса!D26 -> 0
A27: =Касса!A27 -> 0 | E27: =Касса!D27 -> 0
A28: САЛАТЫ и ХОЛОДНЫЕ ЗАКУСКИ | E28: =Касса!D28 -> 0
A29: =Касса!A29 -> 0 | E29: =Касса!D29 -> 0
A30: =Касса!A30 -> 0 | E30: ГАРНИРЫ
A31: =Касса!A31 -> 0 | E31: =Касса!D31 -> 0
A32: =Касса!A32 -> 0 | E32: =Касса!D32 -> 0
A33: =Касса!A33 -> 0 | E33: =Касса!D33 -> 0
A34: =Касса!A34 -> 0 | E34: =Касса!D34 -> 0
A35: =Касса!A35 -> 0 | E35: =Касса!D35 -> 0
A36: =Касса!A36 -> 0 | E36: =Касса!D36 -> 0
A37: =Касса!A37 -> 0 | E37: =Касса!D37 -> 0
A38: =Касса!A38 -> 0 | E38: =Касса!D38 -> 0
A39: =Касса!A39 -> 0
A40: =Касса!A40 -> 0
A41: =Касса!A41 -> 0
